# Исключения в Python

## Цель урока

Цель урока — Познакомиться с основами обработки исключений в Python.  
Вы узнаете, как использовать блоки `try-except` для обработки исключений и как обрабатывать разные типы исключений.

## Обработка исключений с помощью блоков `try-except`

Для обработки исключений в Python используется блок `try-except`.  
Блок `try` содержит код, который может вызвать исключение.  
Если исключение возникает в блоке `try`, то выполнение кода в этом блоке прерывается, и управление передается блоку `except`.

Структура блока `try-except` выглядит следующим образом:

```python
try:
    # Код, который может вызвать исключение
except ExceptionType:
    # Код, который выполняется в случае возникновения исключения
```

- `ExceptionType` - это тип исключения, который вы хотите обработать.  
  Можно указать конкретный тип исключения, например, `ZeroDivisionError` или `ValueError`.

Пример использования блока `try-except`:

```python
try:
    x = 10 / 0  # Деление на ноль
except ZeroDivisionError:
    print("Ошибка: Деление на ноль!")
```

В этом примере происходит попытка выполнить деление на ноль, что приведет к возникновению исключения `ZeroDivisionError`.  
В блоке `except` указано, что нужно выполнить, если возникнет исключение `ZeroDivisionError`.

## Обработка нескольких типов исключений

Вы также можете обработать несколько типов исключений, используя несколько блоков `except`.  
Это полезно, когда вы хотите предоставить различные обработчики для разных типов исключений.

Структура блока `try-except` с несколькими блоками `except` выглядит так:

```python
try:
    # Код, который может вызвать исключение
except ExceptionType1:
    # Код, который выполняется в случае возникновения исключения типа ExceptionType1
except ExceptionType2:
    # Код, который выполняется в случае возникновения исключения типа ExceptionType
```

Пример использования нескольких блоков `except`:

```python
try:
    x = int(input("Введите число: "))
    result = 10 / x
except ZeroDivisionError:
    print("Ошибка: Деление на ноль!")
except ValueError:
    print("Ошибка: Введено некорректное число!")
```

В этом примере сначала происходит попытка преобразовать ввод пользователя в целое число.  
Если пользователь вводит некорректное число (например, буквы вместо числа), возникнет исключение `ValueError`.  
Если пользователь вводит ноль, возникнет исключение `ZeroDivisionError`.  
Разные блоки `except` используются, чтобы обработать каждое исключение отдельно.

## Конструкция `else` и `finally`

Кроме блоков `try` и `except`, в Python также доступны блоки `else` и `finally`.

- Блок `else` выполняется, если никакое исключение не возникло в блоке `try`.
- Блок `finally` выполняется всегда, независимо от того, возникло исключение или нет.

```python
try:
    # Код, который может вызвать исключение
except ExceptionType:
    # Код, который выполняется в случае возникновения исключения
else:
    # Код, который выполняется, если никакое исключение не возникло
finally:
    # Код, который выполняется всегда
```

Пример использования блоков `else` и `finally`:

```python
try:
    x = int(input("Введите число: "))
    result = 10 / x
except ZeroDivisionError:
    print("Ошибка: Деление на ноль!")
except ValueError:
    print("Ошибка: Введено некорректное число!")
else:
    print("Результат: ", result)
finally:
    print("Конец программы")
```

В этом примере блок `else` выполняется, если пользователь вводит корректное число и никакое исключение не возникает.  
Блок `finally` выполняется всегда, независимо от того, возникает исключение или нет.

## Задание
Допишите код с `input`, чтобы запросить число и протестируйте программу на предмет вызова различных ошибок.
